GLOB sdist-make: /home/oliver/work/tox/tox-reproducers/setup.py
py27 create: /home/oliver/work/tox/tox-reproducers/.tox/py27
py27 installdeps: pytest
py27 inst: /home/oliver/work/tox/tox-reproducers/.tox/dist/tox-426-0.0.0.zip
py27 installed: attrs==17.3.0,funcsigs==1.0.2,pluggy==0.6.0,py==1.5.2,pytest==3.3.1,six==1.11.0,tox-426==0.0.0
py27 runtests: PYTHONHASHSEED='4137737740'
py27 runtests: commands[0] | pytest
============================= test session starts ==============================
platform linux2 -- Python 2.7.14, pytest-3.3.1, py-1.5.2, pluggy-0.6.0
rootdir: /home/oliver/work/tox/tox-reproducers, inifile:
collected 1 item

test_file.py F                                                           [100%]

=================================== FAILURES ===================================
__________________________________ test_crash __________________________________

    def test_crash():
        print("whatever")
>       assert 0
E       assert 0

test_file.py:3: AssertionError
----------------------------- Captured stdout call -----------------------------
whatever
=========================== 1 failed in 0.02 seconds ===========================
ERROR: InvocationError: '/home/oliver/work/tox/tox-reproducers/.tox/py27/bin/pytest'
py36 create: /home/oliver/work/tox/tox-reproducers/.tox/py36
py36 installdeps: pytest
py36 inst: /home/oliver/work/tox/tox-reproducers/.tox/dist/tox-426-0.0.0.zip
py36 installed: attrs==17.3.0,pluggy==0.6.0,py==1.5.2,pytest==3.3.1,six==1.11.0,tox-426==0.0.0
py36 runtests: PYTHONHASHSEED='4137737740'
py36 runtests: commands[0] | pytest
============================= test session starts ==============================
platform linux -- Python 3.6.3, pytest-3.3.1, py-1.5.2, pluggy-0.6.0
rootdir: /home/oliver/work/tox/tox-reproducers, inifile:
collected 1 item

test_file.py F                                                           [100%]

=================================== FAILURES ===================================
__________________________________ test_crash __________________________________

    def test_crash():
        print("whatever")
>       assert 0
E       assert 0

test_file.py:3: AssertionError
----------------------------- Captured stdout call -----------------------------
whatever
=========================== 1 failed in 0.02 seconds ===========================
ERROR: InvocationError: '/home/oliver/work/tox/tox-reproducers/.tox/py36/bin/pytest'
lint create: /home/oliver/work/tox/tox-reproducers/.tox/lint
lint installdeps: pytest
lint inst: /home/oliver/work/tox/tox-reproducers/.tox/dist/tox-426-0.0.0.zip
lint installed: attrs==17.3.0,pluggy==0.6.0,py==1.5.2,pytest==3.3.1,six==1.11.0,tox-426==0.0.0
lint runtests: PYTHONHASHSEED='4137737740'
lint runtests: commands[0] | pytest
============================= test session starts ==============================
platform linux -- Python 3.6.3, pytest-3.3.1, py-1.5.2, pluggy-0.6.0
rootdir: /home/oliver/work/tox/tox-reproducers, inifile:
collected 1 item

test_file.py F                                                           [100%]

=================================== FAILURES ===================================
__________________________________ test_crash __________________________________

    def test_crash():
        print("whatever")
>       assert 0
E       assert 0

test_file.py:3: AssertionError
----------------------------- Captured stdout call -----------------------------
whatever
=========================== 1 failed in 0.02 seconds ===========================
ERROR: InvocationError: '/home/oliver/work/tox/tox-reproducers/.tox/lint/bin/pytest'
___________________________________ summary ____________________________________
ERROR:   py27: commands failed
ERROR:   py36: commands failed
ERROR:   lint: commands failed
